<?xml version="1.0" encoding="utf-8"?>
<!-- This URDF was automatically created by SolidWorks to URDF Exporter! Originally created by Stephen Brawner (brawner@gmail.com) 
     Commit Version: 1.6.0-4-g7f85cfe  Build Version: 1.6.7995.38578
     For more information, please see http://wiki.ros.org/sw_urdf_exporter -->
<robot
  name="miniarm_resources">
  <link
    name="base_link">
    <inertial>
      <origin
        xyz="-0.014626692507017 -0.0300798921341412 0.0243491774058119"
        rpy="0 0 0" />
      <mass
        value="0.0959928453861352" />
      <inertia
        ixx="0.000127873724890956"
        ixy="3.91083978866153E-06"
        ixz="4.61026158604999E-10"
        iyy="0.000207741299060964"
        iyz="6.14465976933924E-11"
        izz="0.00013751477455662" />
    </inertial>
    <visual>
      <origin
        xyz="0 0 0"
        rpy="0 0 0" />
      <geometry>
        <mesh
          filename="package://miniarm_resources/meshes/base_link.STL" />
      </geometry>
      <material
        name="">
        <color
          rgba="0 0.501960784313725 0.752941176470588 1" />
      </material>
    </visual>
    <collision>
      <origin
        xyz="0 0 0"
        rpy="0 0 0" />
      <geometry>
        <mesh
          filename="package://miniarm_resources/meshes/base_link.STL" />
      </geometry>
    </collision>
  </link>
  <link
    name="link_1">
    <inertial>
      <origin
        xyz="-0.00643624708847197 0.0172894480194959 -0.00137164372922476"
        rpy="0 0 0" />
      <mass
        value="0.0680127456130139" />
      <inertia
        ixx="5.80904156518187E-05"
        ixy="5.17498588669733E-06"
        ixz="-6.41342976465573E-07"
        iyy="5.46243251656369E-05"
        iyz="6.2383718454181E-06"
        izz="4.49828756990982E-05" />
    </inertial>
    <visual>
      <origin
        xyz="0 0 0"
        rpy="0 0 0" />
      <geometry>
        <mesh
          filename="package://miniarm_resources/meshes/link_1.STL" />
      </geometry>
      <material
        name="">
        <color
          rgba="0.792156862745098 0.819607843137255 0.933333333333333 1" />
      </material>
    </visual>
    <collision>
      <origin
        xyz="0 0 0"
        rpy="0 0 0" />
      <geometry>
        <mesh
          filename="package://miniarm_resources/meshes/link_1.STL" />
      </geometry>
    </collision>
  </link>
  <joint
    name="joint_1"
    type="revolute">
    <origin
      xyz="-0.014874 -0.024223 0.0036168"
      rpy="1.5708 0 0" />
    <parent
      link="base_link" />
    <child
      link="link_1" />
    <axis
      xyz="0 1 0" />
    <limit
      lower="-1.5708"
      upper="1.5708"
      effort="1"
      velocity="10" />
  </joint>
  <link
    name="link_2">
    <inertial>
      <origin
        xyz="-0.00017281 0.058766 0.0037633"
        rpy="0 0 0" />
      <mass
        value="0.06437" />
      <inertia
        ixx="0.000107"
        ixy="1.5699E-09"
        ixz="2.7508E-10"
        iyy="9.1E-06"
        iyz="2.3975E-07"
        izz="0.0001118" />
    </inertial>
    <visual>
      <origin
        xyz="0 0 0"
        rpy="0 0 0" />
      <geometry>
        <mesh
          filename="package://miniarm_resources/meshes/link_2.STL" />
      </geometry>
      <material
        name="">
        <color
          rgba="0.79216 0.81961 0.93333 1" />
      </material>
    </visual>
    <collision>
      <origin
        xyz="0 0 0"
        rpy="0 0 0" />
      <geometry>
        <mesh
          filename="package://miniarm_resources/meshes/link_2.STL" />
      </geometry>
    </collision>
  </link>
  <joint
    name="joint_2"
    type="revolute">
    <origin
      xyz="0 0.04 -0.0135"
      rpy="0 1.5708 0" />
    <parent
      link="link_1" />
    <child
      link="link_2" />
    <axis
      xyz="0 0 1" />
    <limit
      lower="-1.5708"
      upper="1.5708"
      effort="1"
      velocity="10" />
  </joint>
  <link
    name="link_3">
    <inertial>
      <origin
        xyz="0.019316 0.064533 0.013787"
        rpy="0 0 0" />
      <mass
        value="0.050252" />
      <inertia
        ixx="5.4569E-05"
        ixy="-6.8972E-08"
        ixz="1.3644E-10"
        iyy="9.28E-06"
        iyz="-2.8679E-07"
        izz="5.8114E-05" />
    </inertial>
    <visual>
      <origin
        xyz="0 0 0"
        rpy="0 0 0" />
      <geometry>
        <mesh
          filename="package://miniarm_resources/meshes/link_3.STL" />
      </geometry>
      <material
        name="">
        <color
          rgba="0.79216 0.81961 0.93333 1" />
      </material>
    </visual>
    <collision>
      <origin
        xyz="0 0 0"
        rpy="0 0 0" />
      <geometry>
        <mesh
          filename="package://miniarm_resources/meshes/link_3.STL" />
      </geometry>
    </collision>
  </link>
  <joint
    name="joint_3"
    type="revolute">
    <origin
      xyz="-0.025 0.1005 0.0023782"
      rpy="3.1416 0 1.5708" />
    <parent
      link="link_2" />
    <child
      link="link_3" />
    <axis
      xyz="0 0 0" />
    <limit
      lower="-1.5708"
      upper="1.5708"
      effort="1"
      velocity="10" />
  </joint>
  <link
    name="link_4">
    <inertial>
      <origin
        xyz="0.016545 0.017838 0.0087357"
        rpy="0 0 0" />
      <mass
        value="0.016498" />
      <inertia
        ixx="3.9111E-06"
        ixy="1.1665E-08"
        ixz="-3.9818E-09"
        iyy="2.6119E-06"
        iyz="5.7546E-07"
        izz="5.021E-06" />
    </inertial>
    <visual>
      <origin
        xyz="0 0 0"
        rpy="0 0 0" />
      <geometry>
        <mesh
          filename="package://miniarm_resources/meshes/link_4.STL" />
      </geometry>
      <material
        name="">
        <color
          rgba="0.79216 0.81961 0.93333 1" />
      </material>
    </visual>
    <collision>
      <origin
        xyz="0 0 0"
        rpy="0 0 0" />
      <geometry>
        <mesh
          filename="package://miniarm_resources/meshes/link_4.STL" />
      </geometry>
    </collision>
  </link>
  <joint
    name="joint_4"
    type="revolute">
    <origin
      xyz="0.0025 0.115 0"
      rpy="0 0 0" />
    <parent
      link="link_3" />
    <child
      link="link_4" />
    <axis
      xyz="0 0 0" />
    <limit
      lower="-1.5708"
      upper="1.5708"
      effort="1"
      velocity="10" />
  </joint>
  <link
    name="link_5">
    <inertial>
      <origin
        xyz="0.019884 0.0020876 0.0026207"
        rpy="0 0 0" />
      <mass
        value="0.012492" />
      <inertia
        ixx="1.9925E-06"
        ixy="-3.4318E-07"
        ixz="1.1709E-06"
        iyy="4.7687E-06"
        iyz="1.2316E-07"
        izz="4.0202E-06" />
    </inertial>
    <visual>
      <origin
        xyz="0 0 0"
        rpy="0 0 0" />
      <geometry>
        <mesh
          filename="package://miniarm_resources/meshes/link_5.STL" />
      </geometry>
      <material
        name="">
        <color
          rgba="0.79216 0.81961 0.93333 1" />
      </material>
    </visual>
    <collision>
      <origin
        xyz="0 0 0"
        rpy="0 0 0" />
      <geometry>
        <mesh
          filename="package://miniarm_resources/meshes/link_5.STL" />
      </geometry>
    </collision>
  </link>
  <joint
    name="joint_5"
    type="revolute">
    <origin
      xyz="0.0165 0.028 0"
      rpy="3.1416 0 1.5708" />
    <parent
      link="link_4" />
    <child
      link="link_5" />
    <axis
      xyz="0 0 1" />
    <limit
      lower="-1.5708"
      upper="1.5708"
      effort="1"
      velocity="10" />
  </joint>
  <link
    name="gripper">
    <inertial>
      <origin
        xyz="0.010257 0.00022748 -0.025702"
        rpy="0 0 0" />
      <mass
        value="0.0084921" />
      <inertia
        ixx="1.3221E-06"
        ixy="4.7393E-08"
        ixz="-3.7984E-09"
        iyy="2.3201E-06"
        iyz="-1.3809E-07"
        izz="1.2361E-06" />
    </inertial>
    <visual>
      <origin
        xyz="0 0 0"
        rpy="0 0 0" />
      <geometry>
        <mesh
          filename="package://miniarm_resources/meshes/gripper.STL" />
      </geometry>
      <material
        name="">
        <color
          rgba="0.79216 0.81961 0.93333 1" />
      </material>
    </visual>
    <collision>
      <origin
        xyz="0 0 0"
        rpy="0 0 0" />
      <geometry>
        <mesh
          filename="package://miniarm_resources/meshes/gripper.STL" />
      </geometry>
    </collision>
  </link>
  <joint
    name="joint_6"
    type="revolute">
    <origin
      xyz="0.0875 0.009 0.002"
      rpy="0 1.5708 0" />
    <parent
      link="link_5" />
    <child
      link="gripper" />
    <axis
      xyz="0 0 0" />
    <limit
      lower="-1.5708"
      upper="1.5708"
      effort="1"
      velocity="10" />
  </joint>
</robot>